Workbook

Sheet Vue d'ensemble
A1: Matrice de scoring — Profil du dirigeant & Rayonnement
A2: Version normative V2.1 • Scoring validé • Fiche de diagnostic commercial par prospect • Nom public final : Radar by FeexPay
A5: Architecture retenue
A6: Couche | B6: Sortie | C6: Public / interne | D6: Base | E6: Objectif | F6: Échelle | G6: Décision clé | H6: Statut
A7: Profil du dirigeant | B7: 1 archétype principal + secondaire éventuel | C7: Public | D7: 14 réponses | E7: Créer une restitution ludique | F7: 8 archétypes | G7: +2 dimension principale, +1 secondaire | H7: Validé — norme V2.1
A8: Pilotage FeexPay | B8: Maturité opérationnelle | C8: Interne | D8: 8 indicateurs | E8: Qualifier les besoins réels | F8: 0–100 | G8: Q9D est neutre et exclue du dénominateur | H8: Validé — norme V2.1
A9: Rayonnement | B9: Score, niveau et météo | C9: Public | D9: 6 questions scorées + 1 tag | E9: Mesurer les manifestations visibles | F9: 0–100 / 5 niveaux | G9: Q3 qualifie sans hiérarchiser | H9: Validé — norme V2.1
A10: Lecture croisée | B10: Cohérence causale | C10: Interne + rapport | D10: Pilotage vs rayonnement | E10: Lire la relation fondations → rayonnement | F10: 4 lectures | G10: Seuil de solidité : 60/100 | H10: Validé — norme V2.1
A12: Principes de scoring
A13: 1 | B13: Les formulations validées sont reprises sans modification.
A14: 2 | B14: Le profil public et la qualification FeexPay sont deux calculs distincts.
A15: 3 | B15: Une réponse opérationnellement faible ne retire aucun point à un archétype : elle alimente le score interne de pilotage.
A16: 4 | B16: Être seul à encaisser n’est pas assimilé à un manque d’organisation : Q9D est non applicable au score de délégation.
A17: 5 | B17: Le canal de vente, le déclencheur d’adoption et le besoin prioritaire sont des tags commerciaux, pas des notes de valeur.
A18: 6 | B18: Prix, proximité, qualité et avantage distinctif sont quatre natures de différenciation non hiérarchisées.
A19: 7 | B19: Le Rayonnement est traité comme une conséquence observable de la manière dont l’activité est structurée et pilotée.
A20: 8 | B20: Les seuils et poids sont versionnés afin de préserver l’explicabilité des résultats.
A22: Sources de travail
A23: Questions | B23: 14 questions Dirigeant et 7 questions Rayonnement validées par le client le 18 août 2026.
A24: Profils et règles | B24: TDR_Radar_by_FeexPay_V1_Valide.docx — archétypes, empreintes, départages et niveaux.
A25: Évolution V2.1 | B25: Ajout d’une lecture prospect : faits déclarés, difficultés précises, hypothèses à confirmer et questions de relance — sans recommandation de produit.

Sheet Simulateur
A1: Simulateur de validation du scoring
A2: Modifiez uniquement les cellules jaunes « Choix ». Le scoring reste inchangé et les réponses alimentent automatiquement la Fiche prospect.
A3: Profil principal | B3: =INDEX($G$27:$G$34,MATCH(MAX($H$27:$H$34),$H$27:$H$34,0)) | C3: Affinité | D3: =MAX($H$27:$H$34) | E3: Profil secondaire | F3: =IF(AND(LARGE($H$27:$H$34,2)>=55,LARGE($H$27:$H$34,2)>=MAX($H$27:$H$34)*90%,MAX($H$27:$H$34)-LARGE($H$27:$H$34,2)<=8),INDEX($G$27:$G$34,MATCH(LARGE($H$27:$H$34,2),$H$27:$H$34,0)),"Aucun") | G3: Pilotage interne | H3: =IFERROR(SUM($K$10:$K$23)/SUM($L$10:$L$23)*100,0) | I3: Niveau de pilotage | J3: =IF(H3>=75,"Pilotage structuré",IF(H3>=50,"Pilotage partiellement structuré",IF(H3>=25,"Pilotage réactif","Pilotage informel")))
A5: Rayonnement | B5: =SUM($D$50:$D$54) | C5: Niveau | D5: =IF(B5>=80,"Dominant",IF(B5>=60,"Challenger fort",IF(B5>=40,"Acteur silencieux",IF(B5>=20,"Marque fragile","Zone de disparition")))) | E5: Météo | F5: =IF(B5>=80,"Soleil",IF(B5>=60,"Éclaircies",IF(B5>=40,"Nuageux",IF(B5>=20,"Pluie","Tempête")))) | G5: Nuance météo | H5: =IF(B5>=80,"—",IF(AND(H50-B5<=5,H51>=2,H52>=20),"avec potentiel d’éclaircie","—"))
A6: Lecture croisée | B6: =IF(AND($H$3>=60,$B$5>=60),"Cohérence consolidée",IF(AND($H$3>=60,$B$5<60),"Potentiel sous-exploité",IF(AND($H$3<60,$B$5>=60),"Rayonnement sous tension","Fondations à renforcer"))) | F6: Écart R − P | G6: =B5-H3 | H6: Qualificatif | I6: =IF(ABS(G6)<=15,"Cohérence relative",IF(G6>15,"Le rayonnement dépasse les fondations","Les fondations dépassent le rayonnement"))
A9: N° | B9: Question Dirigeant | C9: Choix | D9: Code | E9: Option sélectionnée | F9: Dim. +2 | G9: Dim. +1 | H9: Pts qual. | I9: Poids | J9: Applicable | K9: Contribution | L9: Poids app. | M9: Tag
A10: 1 | B10: Une nouvelle opportunité se présente. Qu’est-ce qui vous pousse le plus à avancer ? | C10: B | D10: =IF(C10="","","Q"&A10&C10) | E10: =IFERROR(INDEX('Dirigeant - Matrice'!$D$5:$D$60,MATCH(D10,'Dirigeant - Matrice'!$A$5:$A$60,0)),"") | F10: =IFERROR(INDEX('Dirigeant - Matrice'!$E$5:$E$60,MATCH(D10,'Dirigeant - Matrice'!$A$5:$A$60,0)),"") | G10: =IFERROR(INDEX('Dirigeant - Matrice'!$G$5:$G$60,MATCH(D10,'Dirigeant - Matrice'!$A$5:$A$60,0)),"") | H10: =IFERROR(INDEX('Dirigeant - Matrice'!$J$5:$J$60,MATCH(D10,'Dirigeant - Matrice'!$A$5:$A$60,0)),"") | I10: =IFERROR(INDEX('Dirigeant - Matrice'!$K$5:$K$60,MATCH(D10,'Dirigeant - Matrice'!$A$5:$A$60,0)),0) | J10: =IFERROR(INDEX('Dirigeant - Matrice'!$L$5:$L$60,MATCH(D10,'Dirigeant - Matrice'!$A$5:$A$60,0)),0) | K10: =IF(OR(H10="",J10=0),0,H10/3*I10) | L10: =I10*J10 | M10: =IFERROR(INDEX('Dirigeant - Matrice'!$N$5:$N$60,MATCH(D10,'Dirigeant - Matrice'!$A$5:$A$60,0)),"")&IF(IFERROR(INDEX('Dirigeant - Matrice'!$P$5:$P$60,MATCH(D10,'Dirigeant - Matrice'!$A$5:$A$60,0)),"")<>""," | "&IFERROR(INDEX('Dirigeant - Matrice'!$P$5:$P$60,MATCH(D10,'Dirigeant - Matrice'!$A$5:$A$60,0)),""),"")
A11: 2 | B11: Vos ventes augmentent brusquement. Quelle devient votre première priorité ? | C11: C | D11: =IF(C11="","","Q"&A11&C11) | E11: =IFERROR(INDEX('Dirigeant - Matrice'!$D$5:$D$60,MATCH(D11,'Dirigeant - Matrice'!$A$5:$A$60,0)),"") | F11: =IFERROR(INDEX('Dirigeant - Matrice'!$E$5:$E$60,MATCH(D11,'Dirigeant - Matrice'!$A$5:$A$60,0)),"") | G11: =IFERROR(INDEX('Dirigeant - Matrice'!$G$5:$G$60,MATCH(D11,'Dirigeant - Matrice'!$A$5:$A$60,0)),"") | H11: =IFERROR(INDEX('Dirigeant - Matrice'!$J$5:$J$60,MATCH(D11,'Dirigeant - Matrice'!$A$5:$A$60,0)),"") | I11: =IFERROR(INDEX('Dirigeant - Matrice'!$K$5:$K$60,MATCH(D11,'Dirigeant - Matrice'!$A$5:$A$60,0)),0) | J11: =IFERROR(INDEX('Dirigeant - Matrice'!$L$5:$L$60,MATCH(D11,'Dirigeant - Matrice'!$A$5:$A$60,0)),0) | K11: =IF(OR(H11="",J11=0),0,H11/3*I11) | L11: =I11*J11 | M11: =IFERROR(INDEX('Dirigeant - Matrice'!$N$5:$N$60,MATCH(D11,'Dirigeant - Matrice'!$A$5:$A$60,0)),"")&IF(IFERROR(INDEX('Dirigeant - Matrice'!$P$5:$P$60,MATCH(D11,'Dirigeant - Matrice'!$A$5:$A$60,0)),"")<>""," | "&IFERROR(INDEX('Dirigeant - Matrice'!$P$5:$P$60,MATCH(D11,'Dirigeant - Matrice'!$A$5:$A$60,0)),""),"")
A12: 3 | B12: Vous devez prendre une décision sans avoir toutes les informations. Que faites-vous ? | C12: B | D12: =IF(C12="","","Q"&A12&C12) | E12: =IFERROR(INDEX('Dirigeant - Matrice'!$D$5:$D$60,MATCH(D12,'Dirigeant - Matrice'!$A$5:$A$60,0)),"") | F12: =IFERROR(INDEX('Dirigeant - Matrice'!$E$5:$E$60,MATCH(D12,'Dirigeant - Matrice'!$A$5:$A$60,0)),"") | G12: =IFERROR(INDEX('Dirigeant - Matrice'!$G$5:$G$60,MATCH(D12,'Dirigeant - Matrice'!$A$5:$A$60,0)),"") | H12: =IFERROR(INDEX('Dirigeant - Matrice'!$J$5:$J$60,MATCH(D12,'Dirigeant - Matrice'!$A$5:$A$60,0)),"") | I12: =IFERROR(INDEX('Dirigeant - Matrice'!$K$5:$K$60,MATCH(D12,'Dirigeant - Matrice'!$A$5:$A$60,0)),0) | J12: =IFERROR(INDEX('Dirigeant - Matrice'!$L$5:$L$60,MATCH(D12,'Dirigeant - Matrice'!$A$5:$A$60,0)),0) | K12: =IF(OR(H12="",J12=0),0,H12/3*I12) | L12: =I12*J12 | M12: =IFERROR(INDEX('Dirigeant - Matrice'!$N$5:$N$60,MATCH(D12,'Dirigeant - Matrice'!$A$5:$A$60,0)),"")&IF(IFERROR(INDEX('Dirigeant - Matrice'!$P$5:$P$60,MATCH(D12,'Dirigeant - Matrice'!$A$5:$A$60,0)),"")<>""," | "&IFERROR(INDEX('Dirigeant - Matrice'!$P$5:$P$60,MATCH(D12,'Dirigeant - Matrice'!$A$5:$A$60,0)),""),"")
A13: 4 | B13: Comment suivez-vous généralement les ventes réalisées au cours d’une semaine ? | C13: A | D13: =IF(C13="","","Q"&A13&C13) | E13: =IFERROR(INDEX('Dirigeant - Matrice'!$D$5:$D$60,MATCH(D13,'Dirigeant - Matrice'!$A$5:$A$60,0)),"") | F13: =IFERROR(INDEX('Dirigeant - Matrice'!$E$5:$E$60,MATCH(D13,'Dirigeant - Matrice'!$A$5:$A$60,0)),"") | G13: =IFERROR(INDEX('Dirigeant - Matrice'!$G$5:$G$60,MATCH(D13,'Dirigeant - Matrice'!$A$5:$A$60,0)),"") | H13: =IFERROR(INDEX('Dirigeant - Matrice'!$J$5:$J$60,MATCH(D13,'Dirigeant - Matrice'!$A$5:$A$60,0)),"") | I13: =IFERROR(INDEX('Dirigeant - Matrice'!$K$5:$K$60,MATCH(D13,'Dirigeant - Matrice'!$A$5:$A$60,0)),0) | J13: =IFERROR(INDEX('Dirigeant - Matrice'!$L$5:$L$60,MATCH(D13,'Dirigeant - Matrice'!$A$5:$A$60,0)),0) | K13: =IF(OR(H13="",J13=0),0,H13/3*I13) | L13: =I13*J13 | M13: =IFERROR(INDEX('Dirigeant - Matrice'!$N$5:$N$60,MATCH(D13,'Dirigeant - Matrice'!$A$5:$A$60,0)),"")&IF(IFERROR(INDEX('Dirigeant - Matrice'!$P$5:$P$60,MATCH(D13,'Dirigeant - Matrice'!$A$5:$A$60,0)),"")<>""," | "&IFERROR(INDEX('Dirigeant - Matrice'!$P$5:$P$60,MATCH(D13,'Dirigeant - Matrice'!$A$5:$A$60,0)),""),"")
A14: 5 | B14: Le montant encaissé ne correspond pas aux ventes réalisées. Quel est votre premier réflexe ? | C14: D | D14: =IF(C14="","","Q"&A14&C14) | E14: =IFERROR(INDEX('Dirigeant - Matrice'!$D$5:$D$60,MATCH(D14,'Dirigeant - Matrice'!$A$5:$A$60,0)),"") | F14: =IFERROR(INDEX('Dirigeant - Matrice'!$E$5:$E$60,MATCH(D14,'Dirigeant - Matrice'!$A$5:$A$60,0)),"") | G14: =IFERROR(INDEX('Dirigeant - Matrice'!$G$5:$G$60,MATCH(D14,'Dirigeant - Matrice'!$A$5:$A$60,0)),"") | H14: =IFERROR(INDEX('Dirigeant - Matrice'!$J$5:$J$60,MATCH(D14,'Dirigeant - Matrice'!$A$5:$A$60,0)),"") | I14: =IFERROR(INDEX('Dirigeant - Matrice'!$K$5:$K$60,MATCH(D14,'Dirigeant - Matrice'!$A$5:$A$60,0)),0) | J14: =IFERROR(INDEX('Dirigeant - Matrice'!$L$5:$L$60,MATCH(D14,'Dirigeant - Matrice'!$A$5:$A$60,0)),0) | K14: =IF(OR(H14="",J14=0),0,H14/3*I14) | L14: =I14*J14 | M14: =IFERROR(INDEX('Dirigeant - Matrice'!$N$5:$N$60,MATCH(D14,'Dirigeant - Matrice'!$A$5:$A$60,0)),"")&IF(IFERROR(INDEX('Dirigeant - Matrice'!$P$5:$P$60,MATCH(D14,'Dirigeant - Matrice'!$A$5:$A$60,0)),"")<>""," | "&IFERROR(INDEX('Dirigeant - Matrice'!$P$5:$P$60,MATCH(D14,'Dirigeant - Matrice'!$A$5:$A$60,0)),""),"")
A15: 6 | B15: Vos clients utilisent plusieurs moyens de paiement. Comment gardez-vous une vue d’ensemble ? | C15: B | D15: =IF(C15="","","Q"&A15&C15) | E15: =IFERROR(INDEX('Dirigeant - Matrice'!$D$5:$D$60,MATCH(D15,'Dirigeant - Matrice'!$A$5:$A$60,0)),"") | F15: =IFERROR(INDEX('Dirigeant - Matrice'!$E$5:$E$60,MATCH(D15,'Dirigeant - Matrice'!$A$5:$A$60,0)),"") | G15: =IFERROR(INDEX('Dirigeant - Matrice'!$G$5:$G$60,MATCH(D15,'Dirigeant - Matrice'!$A$5:$A$60,0)),"") | H15: =IFERROR(INDEX('Dirigeant - Matrice'!$J$5:$J$60,MATCH(D15,'Dirigeant - Matrice'!$A$5:$A$60,0)),"") | I15: =IFERROR(INDEX('Dirigeant - Matrice'!$K$5:$K$60,MATCH(D15,'Dirigeant - Matrice'!$A$5:$A$60,0)),0) | J15: =IFERROR(INDEX('Dirigeant - Matrice'!$L$5:$L$60,MATCH(D15,'Dirigeant - Matrice'!$A$5:$A$60,0)),0) | K15: =IF(OR(H15="",J15=0),0,H15/3*I15) | L15: =I15*J15 | M15: =IFERROR(INDEX('Dirigeant - Matrice'!$N$5:$N$60,MATCH(D15,'Dirigeant - Matrice'!$A$5:$A$60,0)),"")&IF(IFERROR(INDEX('Dirigeant - Matrice'!$P$5:$P$60,MATCH(D15,'Dirigeant - Matrice'!$A$5:$A$60,0)),"")<>""," | "&IFERROR(INDEX('Dirigeant - Matrice'!$P$5:$P$60,MATCH(D15,'Dirigeant - Matrice'!$A$5:$A$60,0)),""),"")
A16: 7 | B16: À quel moment savez-vous réellement ce que votre entreprise peut dépenser ? | C16: A | D16: =IF(C16="","","Q"&A16&C16) | E16: =IFERROR(INDEX('Dirigeant - Matrice'!$D$5:$D$60,MATCH(D16,'Dirigeant - Matrice'!$A$5:$A$60,0)),"") | F16: =IFERROR(INDEX('Dirigeant - Matrice'!$E$5:$E$60,MATCH(D16,'Dirigeant - Matrice'!$A$5:$A$60,0)),"") | G16: =IFERROR(INDEX('Dirigeant - Matrice'!$G$5:$G$60,MATCH(D16,'Dirigeant - Matrice'!$A$5:$A$60,0)),"") | H16: =IFERROR(INDEX('Dirigeant - Matrice'!$J$5:$J$60,MATCH(D16,'Dirigeant - Matrice'!$A$5:$A$60,0)),"") | I16: =IFERROR(INDEX('Dirigeant - Matrice'!$K$5:$K$60,MATCH(D16,'Dirigeant - Matrice'!$A$5:$A$60,0)),0) | J16: =IFERROR(INDEX('Dirigeant - Matrice'!$L$5:$L$60,MATCH(D16,'Dirigeant - Matrice'!$A$5:$A$60,0)),0) | K16: =IF(OR(H16="",J16=0),0,H16/3*I16) | L16: =I16*J16 | M16: =IFERROR(INDEX('Dirigeant - Matrice'!$N$5:$N$60,MATCH(D16,'Dirigeant - Matrice'!$A$5:$A$60,0)),"")&IF(IFERROR(INDEX('Dirigeant - Matrice'!$P$5:$P$60,MATCH(D16,'Dirigeant - Matrice'!$A$5:$A$60,0)),"")<>""," | "&IFERROR(INDEX('Dirigeant - Matrice'!$P$5:$P$60,MATCH(D16,'Dirigeant - Matrice'!$A$5:$A$60,0)),""),"")
A17: 8 | B17: Lorsque vient le moment de faire la comptabilité, dans quel état se trouvent vos informations ? | C17: D | D17: =IF(C17="","","Q"&A17&C17) | E17: =IFERROR(INDEX('Dirigeant - Matrice'!$D$5:$D$60,MATCH(D17,'Dirigeant - Matrice'!$A$5:$A$60,0)),"") | F17: =IFERROR(INDEX('Dirigeant - Matrice'!$E$5:$E$60,MATCH(D17,'Dirigeant - Matrice'!$A$5:$A$60,0)),"") | G17: =IFERROR(INDEX('Dirigeant - Matrice'!$G$5:$G$60,MATCH(D17,'Dirigeant - Matrice'!$A$5:$A$60,0)),"") | H17: =IFERROR(INDEX('Dirigeant - Matrice'!$J$5:$J$60,MATCH(D17,'Dirigeant - Matrice'!$A$5:$A$60,0)),"") | I17: =IFERROR(INDEX('Dirigeant - Matrice'!$K$5:$K$60,MATCH(D17,'Dirigeant - Matrice'!$A$5:$A$60,0)),0) | J17: =IFERROR(INDEX('Dirigeant - Matrice'!$L$5:$L$60,MATCH(D17,'Dirigeant - Matrice'!$A$5:$A$60,0)),0) | K17: =IF(OR(H17="",J17=0),0,H17/3*I17) | L17: =I17*J17 | M17: =IFERROR(INDEX('Dirigeant - Matrice'!$N$5:$N$60,MATCH(D17,'Dirigeant - Matrice'!$A$5:$A$60,0)),"")&IF(IFERROR(INDEX('Dirigeant - Matrice'!$P$5:$P$60,MATCH(D17,'Dirigeant - Matrice'!$A$5:$A$60,0)),"")<>""," | "&IFERROR(INDEX('Dirigeant - Matrice'!$P$5:$P$60,MATCH(D17,'Dirigeant - Matrice'!$A$5:$A$60,0)),""),"")
A18: 9 | B18: Lorsque d’autres personnes encaissent pour votre entreprise, comment suivez-vous leur activité ? | C18: D | D18: =IF(C18="","","Q"&A18&C18) | E18: =IFERROR(INDEX('Dirigeant - Matrice'!$D$5:$D$60,MATCH(D18,'Dirigeant - Matrice'!$A$5:$A$60,0)),"") | F18: =IFERROR(INDEX('Dirigeant - Matrice'!$E$5:$E$60,MATCH(D18,'Dirigeant - Matrice'!$A$5:$A$60,0)),"") | G18: =IFERROR(INDEX('Dirigeant - Matrice'!$G$5:$G$60,MATCH(D18,'Dirigeant - Matrice'!$A$5:$A$60,0)),"") | H18: =IFERROR(INDEX('Dirigeant - Matrice'!$J$5:$J$60,MATCH(D18,'Dirigeant - Matrice'!$A$5:$A$60,0)),"") | I18: =IFERROR(INDEX('Dirigeant - Matrice'!$K$5:$K$60,MATCH(D18,'Dirigeant - Matrice'!$A$5:$A$60,0)),0) | J18: =IFERROR(INDEX('Dirigeant - Matrice'!$L$5:$L$60,MATCH(D18,'Dirigeant - Matrice'!$A$5:$A$60,0)),0) | K18: =IF(OR(H18="",J18=0),0,H18/3*I18) | L18: =I18*J18 | M18: =IFERROR(INDEX('Dirigeant - Matrice'!$N$5:$N$60,MATCH(D18,'Dirigeant - Matrice'!$A$5:$A$60,0)),"")&IF(IFERROR(INDEX('Dirigeant - Matrice'!$P$5:$P$60,MATCH(D18,'Dirigeant - Matrice'!$A$5:$A$60,0)),"")<>""," | "&IFERROR(INDEX('Dirigeant - Matrice'!$P$5:$P$60,MATCH(D18,'Dirigeant - Matrice'!$A$5:$A$60,0)),""),"")
A19: 10 | B19: Lorsqu’un client souhaite vous payer à distance, comment procédez-vous généralement ? | C19: B | D19: =IF(C19="","","Q"&A19&C19) | E19: =IFERROR(INDEX('Dirigeant - Matrice'!$D$5:$D$60,MATCH(D19,'Dirigeant - Matrice'!$A$5:$A$60,0)),"") | F19: =IFERROR(INDEX('Dirigeant - Matrice'!$E$5:$E$60,MATCH(D19,'Dirigeant - Matrice'!$A$5:$A$60,0)),"") | G19: =IFERROR(INDEX('Dirigeant - Matrice'!$G$5:$G$60,MATCH(D19,'Dirigeant - Matrice'!$A$5:$A$60,0)),"") | H19: =IFERROR(INDEX('Dirigeant - Matrice'!$J$5:$J$60,MATCH(D19,'Dirigeant - Matrice'!$A$5:$A$60,0)),"") | I19: =IFERROR(INDEX('Dirigeant - Matrice'!$K$5:$K$60,MATCH(D19,'Dirigeant - Matrice'!$A$5:$A$60,0)),0) | J19: =IFERROR(INDEX('Dirigeant - Matrice'!$L$5:$L$60,MATCH(D19,'Dirigeant - Matrice'!$A$5:$A$60,0)),0) | K19: =IF(OR(H19="",J19=0),0,H19/3*I19) | L19: =I19*J19 | M19: =IFERROR(INDEX('Dirigeant - Matrice'!$N$5:$N$60,MATCH(D19,'Dirigeant - Matrice'!$A$5:$A$60,0)),"")&IF(IFERROR(INDEX('Dirigeant - Matrice'!$P$5:$P$60,MATCH(D19,'Dirigeant - Matrice'!$A$5:$A$60,0)),"")<>""," | "&IFERROR(INDEX('Dirigeant - Matrice'!$P$5:$P$60,MATCH(D19,'Dirigeant - Matrice'!$A$5:$A$60,0)),""),"")
A20: 11 | B20: Quelle place le digital occupe-t-il actuellement dans vos ventes ? | C20: C | D20: =IF(C20="","","Q"&A20&C20) | E20: =IFERROR(INDEX('Dirigeant - Matrice'!$D$5:$D$60,MATCH(D20,'Dirigeant - Matrice'!$A$5:$A$60,0)),"") | F20: =IFERROR(INDEX('Dirigeant - Matrice'!$E$5:$E$60,MATCH(D20,'Dirigeant - Matrice'!$A$5:$A$60,0)),"") | G20: =IFERROR(INDEX('Dirigeant - Matrice'!$G$5:$G$60,MATCH(D20,'Dirigeant - Matrice'!$A$5:$A$60,0)),"") | H20: =IFERROR(INDEX('Dirigeant - Matrice'!$J$5:$J$60,MATCH(D20,'Dirigeant - Matrice'!$A$5:$A$60,0)),"") | I20: =IFERROR(INDEX('Dirigeant - Matrice'!$K$5:$K$60,MATCH(D20,'Dirigeant - Matrice'!$A$5:$A$60,0)),0) | J20: =IFERROR(INDEX('Dirigeant - Matrice'!$L$5:$L$60,MATCH(D20,'Dirigeant - Matrice'!$A$5:$A$60,0)),0) | K20: =IF(OR(H20="",J20=0),0,H20/3*I20) | L20: =I20*J20 | M20: =IFERROR(INDEX('Dirigeant - Matrice'!$N$5:$N$60,MATCH(D20,'Dirigeant - Matrice'!$A$5:$A$60,0)),"")&IF(IFERROR(INDEX('Dirigeant - Matrice'!$P$5:$P$60,MATCH(D20,'Dirigeant - Matrice'!$A$5:$A$60,0)),"")<>""," | "&IFERROR(INDEX('Dirigeant - Matrice'!$P$5:$P$60,MATCH(D20,'Dirigeant - Matrice'!$A$5:$A$60,0)),""),"")
A21: 12 | B21: Un client affirme avoir payé, mais vous ne retrouvez pas immédiatement son paiement. Que faites-vous ? | C21: A | D21: =IF(C21="","","Q"&A21&C21) | E21: =IFERROR(INDEX('Dirigeant - Matrice'!$D$5:$D$60,MATCH(D21,'Dirigeant - Matrice'!$A$5:$A$60,0)),"") | F21: =IFERROR(INDEX('Dirigeant - Matrice'!$E$5:$E$60,MATCH(D21,'Dirigeant - Matrice'!$A$5:$A$60,0)),"") | G21: =IFERROR(INDEX('Dirigeant - Matrice'!$G$5:$G$60,MATCH(D21,'Dirigeant - Matrice'!$A$5:$A$60,0)),"") | H21: =IFERROR(INDEX('Dirigeant - Matrice'!$J$5:$J$60,MATCH(D21,'Dirigeant - Matrice'!$A$5:$A$60,0)),"") | I21: =IFERROR(INDEX('Dirigeant - Matrice'!$K$5:$K$60,MATCH(D21,'Dirigeant - Matrice'!$A$5:$A$60,0)),0) | J21: =IFERROR(INDEX('Dirigeant - Matrice'!$L$5:$L$60,MATCH(D21,'Dirigeant - Matrice'!$A$5:$A$60,0)),0) | K21: =IF(OR(H21="",J21=0),0,H21/3*I21) | L21: =I21*J21 | M21: =IFERROR(INDEX('Dirigeant - Matrice'!$N$5:$N$60,MATCH(D21,'Dirigeant - Matrice'!$A$5:$A$60,0)),"")&IF(IFERROR(INDEX('Dirigeant - Matrice'!$P$5:$P$60,MATCH(D21,'Dirigeant - Matrice'!$A$5:$A$60,0)),"")<>""," | "&IFERROR(INDEX('Dirigeant - Matrice'!$P$5:$P$60,MATCH(D21,'Dirigeant - Matrice'!$A$5:$A$60,0)),""),"")
... A23: 14 | B23: Dans un an, quel progrès vous donnerait le plus le sentiment de mieux piloter votre entreprise ? | C23: A | D23: =IF(C23="","","Q"&A23&C23) | E23: =IFERROR(INDEX('Dirigeant - Matrice'!$D$5:$D$60,MATCH(D23,'Dirigeant - Matrice'!$A$5:$A$60,0)),"") | F23: =IFERROR(INDEX('Dirigeant - Matrice'!$E$5:$E$60,MATCH(D23,'Dirigeant - Matrice'!$A$5:$A$60,0)),"") | G23: =IFERROR(INDEX('Dirigeant - Matrice'!$G$5:$G$60,MATCH(D23,'Dirigeant - Matrice'!$A$5:$A$60,0)),"") | H23: =IFERROR(INDEX('Dirigeant - Matrice'!$J$5:$J$60,MATCH(D23,'Dirigeant - Matrice'!$A$5:$A$60,0)),"") | I23: =IFERROR(INDEX('Dirigeant - Matrice'!$K$5:$K$60,MATCH(D23,'Dirigeant - Matrice'!$A$5:$A$60,0)),0) | J23: =IFERROR(INDEX('Dirigeant - Matrice'!$L$5:$L$60,MATCH(D23,'Dirigeant - Matrice'!$A$5:$A$60,0)),0) | K23: =IF(OR(H23="",J23=0),0,H23/3*I23) | L23: =I23*J23 | M23: =IFERROR(INDEX('Dirigeant - Matrice'!$N$5:$N$60,MATCH(D23,'Dirigeant - Matrice'!$A$5:$A$60,0)),"")&IF(IFERROR(INDEX('Dirigeant - Matrice'!$P$5:$P$60,MATCH(D23,'Dirigeant - Matrice'!$A$5:$A$60,0)),"")<>""," | "&IFERROR(INDEX('Dirigeant - Matrice'!$P$5:$P$60,MATCH(D23,'Dirigeant - Matrice'!$A$5:$A$60,0)),""),"")
A25: Scores des dimensions | G25: Affinités des archétypes
A26: Dimension | B26: Code | C26: Score brut | D26: Maximum | E26: Score normalisé | G26: Archétype | H26: Affinité | I26: Dimension centrale
A27: Vision | B27: VIS | C27: =COUNTIF($F$10:$F$23,B27)*2+COUNTIF($G$10:$G$23,B27) | D27: =INDEX('Contrôles'!$E$5:$E$12,MATCH(B27,'Contrôles'!$B$5:$B$12,0)) | E27: =IFERROR(C27/D27*100,0) | G27: Stratège | H27: =$E$28*50%+$E$33*30%+$E$30*20% | I27: STR
A28: Stratégie | B28: STR | C28: =COUNTIF($F$10:$F$23,B28)*2+COUNTIF($G$10:$G$23,B28) | D28: =INDEX('Contrôles'!$E$5:$E$12,MATCH(B28,'Contrôles'!$B$5:$B$12,0)) | E28: =IFERROR(C28/D28*100,0) | G28: Visionnaire | H28: =$E$27*50%+$E$31*30%+$E$34*20% | I28: VIS
A29: Exécution | B29: EXE | C29: =COUNTIF($F$10:$F$23,B29)*2+COUNTIF($G$10:$G$23,B29) | D29: =INDEX('Contrôles'!$E$5:$E$12,MATCH(B29,'Contrôles'!$B$5:$B$12,0)) | E29: =IFERROR(C29/D29*100,0) | G29: Bâtisseur | H29: =$E$29*50%+$E$30*35%+$E$28*15% | I29: EXE
A30: Organisation | B30: ORG | C30: =COUNTIF($F$10:$F$23,B30)*2+COUNTIF($G$10:$G$23,B30) | D30: =INDEX('Contrôles'!$E$5:$E$12,MATCH(B30,'Contrôles'!$B$5:$B$12,0)) | E30: =IFERROR(C30/D30*100,0) | G30: Conquérant | H30: =$E$32*50%+$E$29*35%+$E$27*15% | I30: AUD
A31: Influence | B31: INF | C31: =COUNTIF($F$10:$F$23,B31)*2+COUNTIF($G$10:$G$23,B31) | D31: =INDEX('Contrôles'!$E$5:$E$12,MATCH(B31,'Contrôles'!$B$5:$B$12,0)) | E31: =IFERROR(C31/D31*100,0) | G31: Fédérateur | H31: =$E$31*50%+$E$33*30%+$E$27*20% | I31: INF
A32: Audace | B32: AUD | C32: =COUNTIF($F$10:$F$23,B32)*2+COUNTIF($G$10:$G$23,B32) | D32: =INDEX('Contrôles'!$E$5:$E$12,MATCH(B32,'Contrôles'!$B$5:$B$12,0)) | E32: =IFERROR(C32/D32*100,0) | G32: Résilient | H32: =$E$33*50%+$E$29*30%+$E$32*20% | I32: ADA
A33: Adaptabilité | B33: ADA | C33: =COUNTIF($F$10:$F$23,B33)*2+COUNTIF($G$10:$G$23,B33) | D33: =INDEX('Contrôles'!$E$5:$E$12,MATCH(B33,'Contrôles'!$B$5:$B$12,0)) | E33: =IFERROR(C33/D33*100,0) | G33: Gestionnaire | H33: =$E$30*45%+$E$28*30%+$E$29*25% | I33: ORG
A34: Transformation | B34: TRA | C34: =COUNTIF($F$10:$F$23,B34)*2+COUNTIF($G$10:$G$23,B34) | D34: =INDEX('Contrôles'!$E$5:$E$12,MATCH(B34,'Contrôles'!$B$5:$B$12,0)) | E34: =IFERROR(C34/D34*100,0) | G34: Réformateur | H34: =$E$34*50%+$E$32*30%+$E$27*20% | I34: TRA
A39: N° | B39: Question Rayonnement | C39: Choix | D39: Code | E39: Option sélectionnée | F39: Points | G39: Dimension | H39: Tag | I39: Valeur | J39: Règle
A40: 1 | B40: En dehors de vos clients actuels, jusqu’où votre entreprise est-elle connue ? | C40: C | D40: =IF(C40="","","R"&A40&C40) | E40: =IFERROR(INDEX('Rayonnement - Matrice'!$D$5:$D$32,MATCH(D40,'Rayonnement - Matrice'!$A$5:$A$32,0)),"") | F40: =IFERROR(INDEX('Rayonnement - Matrice'!$F$5:$F$32,MATCH(D40,'Rayonnement - Matrice'!$A$5:$A$32,0)),"") | G40: =IFERROR(INDEX('Rayonnement - Matrice'!$E$5:$E$32,MATCH(D40,'Rayonnement - Matrice'!$A$5:$A$32,0)),"") | H40: =IFERROR(INDEX('Rayonnement - Matrice'!$H$5:$H$32,MATCH(D40,'Rayonnement - Matrice'!$A$5:$A$32,0)),"") | I40: =IFERROR(INDEX('Rayonnement - Matrice'!$I$5:$I$32,MATCH(D40,'Rayonnement - Matrice'!$A$5:$A$32,0)),"") | J40: =IFERROR(INDEX('Rayonnement - Matrice'!$J$5:$J$32,MATCH(D40,'Rayonnement - Matrice'!$A$5:$A$32,0)),"")
A41: 2 | B41: Lorsqu’un prospect choisit un concurrent, savez-vous généralement pourquoi ? | C41: C | D41: =IF(C41="","","R"&A41&C41) | E41: =IFERROR(INDEX('Rayonnement - Matrice'!$D$5:$D$32,MATCH(D41,'Rayonnement - Matrice'!$A$5:$A$32,0)),"") | F41: =IFERROR(INDEX('Rayonnement - Matrice'!$F$5:$F$32,MATCH(D41,'Rayonnement - Matrice'!$A$5:$A$32,0)),"") | G41: =IFERROR(INDEX('Rayonnement - Matrice'!$E$5:$E$32,MATCH(D41,'Rayonnement - Matrice'!$A$5:$A$32,0)),"") | H41: =IFERROR(INDEX('Rayonnement - Matrice'!$H$5:$H$32,MATCH(D41,'Rayonnement - Matrice'!$A$5:$A$32,0)),"") | I41: =IFERROR(INDEX('Rayonnement - Matrice'!$I$5:$I$32,MATCH(D41,'Rayonnement - Matrice'!$A$5:$A$32,0)),"") | J41: =IFERROR(INDEX('Rayonnement - Matrice'!$J$5:$J$32,MATCH(D41,'Rayonnement - Matrice'!$A$5:$A$32,0)),"")
A42: 3 | B42: Pour quelle raison vos clients vous choisissent-ils principalement ? | C42: C | D42: =IF(C42="","","R"&A42&C42) | E42: =IFERROR(INDEX('Rayonnement - Matrice'!$D$5:$D$32,MATCH(D42,'Rayonnement - Matrice'!$A$5:$A$32,0)),"") | F42: =IFERROR(INDEX('Rayonnement - Matrice'!$F$5:$F$32,MATCH(D42,'Rayonnement - Matrice'!$A$5:$A$32,0)),"") | G42: =IFERROR(INDEX('Rayonnement - Matrice'!$E$5:$E$32,MATCH(D42,'Rayonnement - Matrice'!$A$5:$A$32,0)),"") | H42: =IFERROR(INDEX('Rayonnement - Matrice'!$H$5:$H$32,MATCH(D42,'Rayonnement - Matrice'!$A$5:$A$32,0)),"") | I42: =IFERROR(INDEX('Rayonnement - Matrice'!$I$5:$I$32,MATCH(D42,'Rayonnement - Matrice'!$A$5:$A$32,0)),"") | J42: =IFERROR(INDEX('Rayonnement - Matrice'!$J$5:$J$32,MATCH(D42,'Rayonnement - Matrice'!$A$5:$A$32,0)),"")
A43: 4 | B43: Une personne qui découvre votre entreprise comprend-elle facilement ce qui vous distingue ? | C43: C | D43: =IF(C43="","","R"&A43&C43) | E43: =IFERROR(INDEX('Rayonnement - Matrice'!$D$5:$D$32,MATCH(D43,'Rayonnement - Matrice'!$A$5:$A$32,0)),"") | F43: =IFERROR(INDEX('Rayonnement - Matrice'!$F$5:$F$32,MATCH(D43,'Rayonnement - Matrice'!$A$5:$A$32,0)),"") | G43: =IFERROR(INDEX('Rayonnement - Matrice'!$E$5:$E$32,MATCH(D43,'Rayonnement - Matrice'!$A$5:$A$32,0)),"") | H43: =IFERROR(INDEX('Rayonnement - Matrice'!$H$5:$H$32,MATCH(D43,'Rayonnement - Matrice'!$A$5:$A$32,0)),"") | I43: =IFERROR(INDEX('Rayonnement - Matrice'!$I$5:$I$32,MATCH(D43,'Rayonnement - Matrice'!$A$5:$A$32,0)),"") | J43: =IFERROR(INDEX('Rayonnement - Matrice'!$J$5:$J$32,MATCH(D43,'Rayonnement - Matrice'!$A$5:$A$32,0)),"")
A44: 5 | B44: Comment votre entreprise est-elle actuellement présente sur les canaux numériques ? | C44: C | D44: =IF(C44="","","R"&A44&C44) | E44: =IFERROR(INDEX('Rayonnement - Matrice'!$D$5:$D$32,MATCH(D44,'Rayonnement - Matrice'!$A$5:$A$32,0)),"") | F44: =IFERROR(INDEX('Rayonnement - Matrice'!$F$5:$F$32,MATCH(D44,'Rayonnement - Matrice'!$A$5:$A$32,0)),"") | G44: =IFERROR(INDEX('Rayonnement - Matrice'!$E$5:$E$32,MATCH(D44,'Rayonnement - Matrice'!$A$5:$A$32,0)),"") | H44: =IFERROR(INDEX('Rayonnement - Matrice'!$H$5:$H$32,MATCH(D44,'Rayonnement - Matrice'!$A$5:$A$32,0)),"") | I44: =IFERROR(INDEX('Rayonnement - Matrice'!$I$5:$I$32,MATCH(D44,'Rayonnement - Matrice'!$A$5:$A$32,0)),"") | J44: =IFERROR(INDEX('Rayonnement - Matrice'!$J$5:$J$32,MATCH(D44,'Rayonnement - Matrice'!$A$5:$A$32,0)),"")
A45: 6 | B45: Que produit concrètement votre présence numérique pour votre entreprise ? | C45: C | D45: =IF(C45="","","R"&A45&C45) | E45: =IFERROR(INDEX('Rayonnement - Matrice'!$D$5:$D$32,MATCH(D45,'Rayonnement - Matrice'!$A$5:$A$32,0)),"") | F45: =IFERROR(INDEX('Rayonnement - Matrice'!$F$5:$F$32,MATCH(D45,'Rayonnement - Matrice'!$A$5:$A$32,0)),"") | G45: =IFERROR(INDEX('Rayonnement - Matrice'!$E$5:$E$32,MATCH(D45,'Rayonnement - Matrice'!$A$5:$A$32,0)),"") | H45: =IFERROR(INDEX('Rayonnement - Matrice'!$H$5:$H$32,MATCH(D45,'Rayonnement - Matrice'!$A$5:$A$32,0)),"") | I45: =IFERROR(INDEX('Rayonnement - Matrice'!$I$5:$I$32,MATCH(D45,'Rayonnement - Matrice'!$A$5:$A$32,0)),"") | J45: =IFERROR(INDEX('Rayonnement - Matrice'!$J$5:$J$32,MATCH(D45,'Rayonnement - Matrice'!$A$5:$A$32,0)),"")
A46: 7 | B46: Si votre entreprise arrêtait ses activités demain, qui le remarquerait rapidement ? | C46: C | D46: =IF(C46="","","R"&A46&C46) | E46: =IFERROR(INDEX('Rayonnement - Matrice'!$D$5:$D$32,MATCH(D46,'Rayonnement - Matrice'!$A$5:$A$32,0)),"") | F46: =IFERROR(INDEX('Rayonnement - Matrice'!$F$5:$F$32,MATCH(D46,'Rayonnement - Matrice'!$A$5:$A$32,0)),"") | G46: =IFERROR(INDEX('Rayonnement - Matrice'!$E$5:$E$32,MATCH(D46,'Rayonnement - Matrice'!$A$5:$A$32,0)),"") | H46: =IFERROR(INDEX('Rayonnement - Matrice'!$H$5:$H$32,MATCH(D46,'Rayonnement - Matrice'!$A$5:$A$32,0)),"") | I46: =IFERROR(INDEX('Rayonnement - Matrice'!$I$5:$I$32,MATCH(D46,'Rayonnement - Matrice'!$A$5:$A$32,0)),"") | J46: =IFERROR(INDEX('Rayonnement - Matrice'!$J$5:$J$32,MATCH(D46,'Rayonnement - Matrice'!$A$5:$A$32,0)),"")
A48: Calcul du Rayonnement
A49: Dimension | B49: Score | C49: Poids global | D49: Contribution | E49: Source | G49: Aide technique | H49: Valeur
A50: Notoriété | B50: =F40/3*100 | C50: 0.2 | D50: =B50*C50 | E50: R1 | G50: Seuil suivant | H50: =IF($B$5>=80,100,IF($B$5>=60,80,IF($B$5>=40,60,IF($B$5>=20,40,20))))
...

Sheet Fiche prospect
A1: Fiche de diagnostic commercial du prospect
A2: Lecture générée à partir des réponses déclarées. Elle prépare l’échange commercial : elle décrit des difficultés concrètes et des pistes à vérifier, sans recommander de produit.
M4: Code | N4: Parcours | O4: Dimension | P4: Nature | Q4: Gravité | R4: Niveau | S4: Constat | T4: Difficulté | U4: Hypothèse | V4: Relance | W4: Réponse | X4: Rang difficulté | Y4: Rang force
A5: Profil | B5: ='Simulateur'!B3 | C5: Pilotage | D5: ='Simulateur'!H3 | E5: Niveau de pilotage | F5: ='Simulateur'!J3 | M5: ='Simulateur'!D10 | N5: =IFERROR(INDEX('Bibliothèque constats'!$B$5:$B$88,MATCH($M5,'Bibliothèque constats'!$A$5:$A$88,0)),"") | O5: =IFERROR(INDEX('Bibliothèque constats'!$F$5:$F$88,MATCH($M5,'Bibliothèque constats'!$A$5:$A$88,0)),"") | P5: =IFERROR(INDEX('Bibliothèque constats'!$G$5:$G$88,MATCH($M5,'Bibliothèque constats'!$A$5:$A$88,0)),"") | Q5: =IFERROR(INDEX('Bibliothèque constats'!$H$5:$H$88,MATCH($M5,'Bibliothèque constats'!$A$5:$A$88,0)),"") | R5: =IFERROR(INDEX('Bibliothèque constats'!$I$5:$I$88,MATCH($M5,'Bibliothèque constats'!$A$5:$A$88,0)),"") | S5: =IFERROR(INDEX('Bibliothèque constats'!$J$5:$J$88,MATCH($M5,'Bibliothèque constats'!$A$5:$A$88,0)),"") | T5: =IFERROR(INDEX('Bibliothèque constats'!$K$5:$K$88,MATCH($M5,'Bibliothèque constats'!$A$5:$A$88,0)),"") | U5: =IFERROR(INDEX('Bibliothèque constats'!$L$5:$L$88,MATCH($M5,'Bibliothèque constats'!$A$5:$A$88,0)),"") | V5: =IFERROR(INDEX('Bibliothèque constats'!$M$5:$M$88,MATCH($M5,'Bibliothèque constats'!$A$5:$A$88,0)),"") | W5: =IFERROR(INDEX('Bibliothèque constats'!$E$5:$E$88,MATCH($M5,'Bibliothèque constats'!$A$5:$A$88,0)),"") | X5: =IF(AND(Q5>0,T5<>""),Q5*1000-ROW(),0) | Y5: =IF(P5="Force",1000-ROW(),0)
A6: Rayonnement | B6: ='Simulateur'!B5 | C6: Niveau de rayonnement | D6: ='Simulateur'!D5 | E6: Lecture croisée | F6: ='Simulateur'!B6 | M6: ='Simulateur'!D11 | N6: =IFERROR(INDEX('Bibliothèque constats'!$B$5:$B$88,MATCH($M6,'Bibliothèque constats'!$A$5:$A$88,0)),"") | O6: =IFERROR(INDEX('Bibliothèque constats'!$F$5:$F$88,MATCH($M6,'Bibliothèque constats'!$A$5:$A$88,0)),"") | P6: =IFERROR(INDEX('Bibliothèque constats'!$G$5:$G$88,MATCH($M6,'Bibliothèque constats'!$A$5:$A$88,0)),"") | Q6: =IFERROR(INDEX('Bibliothèque constats'!$H$5:$H$88,MATCH($M6,'Bibliothèque constats'!$A$5:$A$88,0)),"") | R6: =IFERROR(INDEX('Bibliothèque constats'!$I$5:$I$88,MATCH($M6,'Bibliothèque constats'!$A$5:$A$88,0)),"") | S6: =IFERROR(INDEX('Bibliothèque constats'!$J$5:$J$88,MATCH($M6,'Bibliothèque constats'!$A$5:$A$88,0)),"") | T6: =IFERROR(INDEX('Bibliothèque constats'!$K$5:$K$88,MATCH($M6,'Bibliothèque constats'!$A$5:$A$88,0)),"") | U6: =IFERROR(INDEX('Bibliothèque constats'!$L$5:$L$88,MATCH($M6,'Bibliothèque constats'!$A$5:$A$88,0)),"") | V6: =IFERROR(INDEX('Bibliothèque constats'!$M$5:$M$88,MATCH($M6,'Bibliothèque constats'!$A$5:$A$88,0)),"") | W6: =IFERROR(INDEX('Bibliothèque constats'!$E$5:$E$88,MATCH($M6,'Bibliothèque constats'!$A$5:$A$88,0)),"") | X6: =IF(AND(Q6>0,T6<>""),Q6*1000-ROW(),0) | Y6: =IF(P6="Force",1000-ROW(),0)
M7: ='Simulateur'!D12 | N7: =IFERROR(INDEX('Bibliothèque constats'!$B$5:$B$88,MATCH($M7,'Bibliothèque constats'!$A$5:$A$88,0)),"") | O7: =IFERROR(INDEX('Bibliothèque constats'!$F$5:$F$88,MATCH($M7,'Bibliothèque constats'!$A$5:$A$88,0)),"") | P7: =IFERROR(INDEX('Bibliothèque constats'!$G$5:$G$88,MATCH($M7,'Bibliothèque constats'!$A$5:$A$88,0)),"") | Q7: =IFERROR(INDEX('Bibliothèque constats'!$H$5:$H$88,MATCH($M7,'Bibliothèque constats'!$A$5:$A$88,0)),"") | R7: =IFERROR(INDEX('Bibliothèque constats'!$I$5:$I$88,MATCH($M7,'Bibliothèque constats'!$A$5:$A$88,0)),"") | S7: =IFERROR(INDEX('Bibliothèque constats'!$J$5:$J$88,MATCH($M7,'Bibliothèque constats'!$A$5:$A$88,0)),"") | T7: =IFERROR(INDEX('Bibliothèque constats'!$K$5:$K$88,MATCH($M7,'Bibliothèque constats'!$A$5:$A$88,0)),"") | U7: =IFERROR(INDEX('Bibliothèque constats'!$L$5:$L$88,MATCH($M7,'Bibliothèque constats'!$A$5:$A$88,0)),"") | V7: =IFERROR(INDEX('Bibliothèque constats'!$M$5:$M$88,MATCH($M7,'Bibliothèque constats'!$A$5:$A$88,0)),"") | W7: =IFERROR(INDEX('Bibliothèque constats'!$E$5:$E$88,MATCH($M7,'Bibliothèque constats'!$A$5:$A$88,0)),"") | X7: =IF(AND(Q7>0,T7<>""),Q7*1000-ROW(),0) | Y7: =IF(P7="Force",1000-ROW(),0)
A8: Difficultés prioritaires détectées | M8: ='Simulateur'!D13 | N8: =IFERROR(INDEX('Bibliothèque constats'!$B$5:$B$88,MATCH($M8,'Bibliothèque constats'!$A$5:$A$88,0)),"") | O8: =IFERROR(INDEX('Bibliothèque constats'!$F$5:$F$88,MATCH($M8,'Bibliothèque constats'!$A$5:$A$88,0)),"") | P8: =IFERROR(INDEX('Bibliothèque constats'!$G$5:$G$88,MATCH($M8,'Bibliothèque constats'!$A$5:$A$88,0)),"") | Q8: =IFERROR(INDEX('Bibliothèque constats'!$H$5:$H$88,MATCH($M8,'Bibliothèque constats'!$A$5:$A$88,0)),"") | R8: =IFERROR(INDEX('Bibliothèque constats'!$I$5:$I$88,MATCH($M8,'Bibliothèque constats'!$A$5:$A$88,0)),"") | S8: =IFERROR(INDEX('Bibliothèque constats'!$J$5:$J$88,MATCH($M8,'Bibliothèque constats'!$A$5:$A$88,0)),"") | T8: =IFERROR(INDEX('Bibliothèque constats'!$K$5:$K$88,MATCH($M8,'Bibliothèque constats'!$A$5:$A$88,0)),"") | U8: =IFERROR(INDEX('Bibliothèque constats'!$L$5:$L$88,MATCH($M8,'Bibliothèque constats'!$A$5:$A$88,0)),"") | V8: =IFERROR(INDEX('Bibliothèque constats'!$M$5:$M$88,MATCH($M8,'Bibliothèque constats'!$A$5:$A$88,0)),"") | W8: =IFERROR(INDEX('Bibliothèque constats'!$E$5:$E$88,MATCH($M8,'Bibliothèque constats'!$A$5:$A$88,0)),"") | X8: =IF(AND(Q8>0,T8<>""),Q8*1000-ROW(),0) | Y8: =IF(P8="Force",1000-ROW(),0)
A9: # | B9: Difficulté précise | C9: Gravité | D9: Constat factuel | E9: Réponse sélectionnée | F9: Question de relance | M9: ='Simulateur'!D14 | N9: =IFERROR(INDEX('Bibliothèque constats'!$B$5:$B$88,MATCH($M9,'Bibliothèque constats'!$A$5:$A$88,0)),"") | O9: =IFERROR(INDEX('Bibliothèque constats'!$F$5:$F$88,MATCH($M9,'Bibliothèque constats'!$A$5:$A$88,0)),"") | P9: =IFERROR(INDEX('Bibliothèque constats'!$G$5:$G$88,MATCH($M9,'Bibliothèque constats'!$A$5:$A$88,0)),"") | Q9: =IFERROR(INDEX('Bibliothèque constats'!$H$5:$H$88,MATCH($M9,'Bibliothèque constats'!$A$5:$A$88,0)),"") | R9: =IFERROR(INDEX('Bibliothèque constats'!$I$5:$I$88,MATCH($M9,'Bibliothèque constats'!$A$5:$A$88,0)),"") | S9: =IFERROR(INDEX('Bibliothèque constats'!$J$5:$J$88,MATCH($M9,'Bibliothèque constats'!$A$5:$A$88,0)),"") | T9: =IFERROR(INDEX('Bibliothèque constats'!$K$5:$K$88,MATCH($M9,'Bibliothèque constats'!$A$5:$A$88,0)),"") | U9: =IFERROR(INDEX('Bibliothèque constats'!$L$5:$L$88,MATCH($M9,'Bibliothèque constats'!$A$5:$A$88,0)),"") | V9: =IFERROR(INDEX('Bibliothèque constats'!$M$5:$M$88,MATCH($M9,'Bibliothèque constats'!$A$5:$A$88,0)),"") | W9: =IFERROR(INDEX('Bibliothèque constats'!$E$5:$E$88,MATCH($M9,'Bibliothèque constats'!$A$5:$A$88,0)),"") | X9: =IF(AND(Q9>0,T9<>""),Q9*1000-ROW(),0) | Y9: =IF(P9="Force",1000-ROW(),0)
A10: =IF(LARGE($X$5:$X$25,1)<=0,"",1) | B10: =IFERROR(IF(LARGE($X$5:$X$25,1)<=0,"",INDEX($T$5:$T$25,MATCH(LARGE($X$5:$X$25,1),$X$5:$X$25,0))),"") | C10: =IFERROR(IF(LARGE($X$5:$X$25,1)<=0,"",INDEX($R$5:$R$25,MATCH(LARGE($X$5:$X$25,1),$X$5:$X$25,0))),"") | D10: =IFERROR(IF(LARGE($X$5:$X$25,1)<=0,"",INDEX($S$5:$S$25,MATCH(LARGE($X$5:$X$25,1),$X$5:$X$25,0))),"") | E10: =IFERROR(IF(LARGE($X$5:$X$25,1)<=0,"",INDEX($W$5:$W$25,MATCH(LARGE($X$5:$X$25,1),$X$5:$X$25,0))),"") | F10: =IFERROR(IF(LARGE($X$5:$X$25,1)<=0,"",INDEX($V$5:$V$25,MATCH(LARGE($X$5:$X$25,1),$X$5:$X$25,0))),"") | M10: ='Simulateur'!D15 | N10: =IFERROR(INDEX('Bibliothèque constats'!$B$5:$B$88,MATCH($M10,'Bibliothèque constats'!$A$5:$A$88,0)),"") | O10: =IFERROR(INDEX('Bibliothèque constats'!$F$5:$F$88,MATCH($M10,'Bibliothèque constats'!$A$5:$A$88,0)),"") | P10: =IFERROR(INDEX('Bibliothèque constats'!$G$5:$G$88,MATCH($M10,'Bibliothèque constats'!$A$5:$A$88,0)),"") | Q10: =IFERROR(INDEX('Bibliothèque constats'!$H$5:$H$88,MATCH($M10,'Bibliothèque constats'!$A$5:$A$88,0)),"") | R10: =IFERROR(INDEX('Bibliothèque constats'!$I$5:$I$88,MATCH($M10,'Bibliothèque constats'!$A$5:$A$88,0)),"") | S10: =IFERROR(INDEX('Bibliothèque constats'!$J$5:$J$88,MATCH($M10,'Bibliothèque constats'!$A$5:$A$88,0)),"") | T10: =IFERROR(INDEX('Bibliothèque constats'!$K$5:$K$88,MATCH($M10,'Bibliothèque constats'!$A$5:$A$88,0)),"") | U10: =IFERROR(INDEX('Bibliothèque constats'!$L$5:$L$88,MATCH($M10,'Bibliothèque constats'!$A$5:$A$88,0)),"") | V10: =IFERROR(INDEX('Bibliothèque constats'!$M$5:$M$88,MATCH($M10,'Bibliothèque constats'!$A$5:$A$88,0)),"") | W10: =IFERROR(INDEX('Bibliothèque constats'!$E$5:$E$88,MATCH($M10,'Bibliothèque constats'!$A$5:$A$88,0)),"") | X10: =IF(AND(Q10>0,T10<>""),Q10*1000-ROW(),0) | Y10: =IF(P10="Force",1000-ROW(),0)
A11: =IF(LARGE($X$5:$X$25,2)<=0,"",2) | B11: =IFERROR(IF(LARGE($X$5:$X$25,2)<=0,"",INDEX($T$5:$T$25,MATCH(LARGE($X$5:$X$25,2),$X$5:$X$25,0))),"") | C11: =IFERROR(IF(LARGE($X$5:$X$25,2)<=0,"",INDEX($R$5:$R$25,MATCH(LARGE($X$5:$X$25,2),$X$5:$X$25,0))),"") | D11: =IFERROR(IF(LARGE($X$5:$X$25,2)<=0,"",INDEX($S$5:$S$25,MATCH(LARGE($X$5:$X$25,2),$X$5:$X$25,0))),"") | E11: =IFERROR(IF(LARGE($X$5:$X$25,2)<=0,"",INDEX($W$5:$W$25,MATCH(LARGE($X$5:$X$25,2),$X$5:$X$25,0))),"") | F11: =IFERROR(IF(LARGE($X$5:$X$25,2)<=0,"",INDEX($V$5:$V$25,MATCH(LARGE($X$5:$X$25,2),$X$5:$X$25,0))),"") | M11: ='Simulateur'!D16 | N11: =IFERROR(INDEX('Bibliothèque constats'!$B$5:$B$88,MATCH($M11,'Bibliothèque constats'!$A$5:$A$88,0)),"") | O11: =IFERROR(INDEX('Bibliothèque constats'!$F$5:$F$88,MATCH($M11,'Bibliothèque constats'!$A$5:$A$88,0)),"") | P11: =IFERROR(INDEX('Bibliothèque constats'!$G$5:$G$88,MATCH($M11,'Bibliothèque constats'!$A$5:$A$88,0)),"") | Q11: =IFERROR(INDEX('Bibliothèque constats'!$H$5:$H$88,MATCH($M11,'Bibliothèque constats'!$A$5:$A$88,0)),"") | R11: =IFERROR(INDEX('Bibliothèque constats'!$I$5:$I$88,MATCH($M11,'Bibliothèque constats'!$A$5:$A$88,0)),"") | S11: =IFERROR(INDEX('Bibliothèque constats'!$J$5:$J$88,MATCH($M11,'Bibliothèque constats'!$A$5:$A$88,0)),"") | T11: =IFERROR(INDEX('Bibliothèque constats'!$K$5:$K$88,MATCH($M11,'Bibliothèque constats'!$A$5:$A$88,0)),"") | U11: =IFERROR(INDEX('Bibliothèque constats'!$L$5:$L$88,MATCH($M11,'Bibliothèque constats'!$A$5:$A$88,0)),"") | V11: =IFERROR(INDEX('Bibliothèque constats'!$M$5:$M$88,MATCH($M11,'Bibliothèque constats'!$A$5:$A$88,0)),"") | W11: =IFERROR(INDEX('Bibliothèque constats'!$E$5:$E$88,MATCH($M11,'Bibliothèque constats'!$A$5:$A$88,0)),"") | X11: =IF(AND(Q11>0,T11<>""),Q11*1000-ROW(),0) | Y11: =IF(P11="Force",1000-ROW(),0)
A12: =IF(LARGE($X$5:$X$25,3)<=0,"",3) | B12: =IFERROR(IF(LARGE($X$5:$X$25,3)<=0,"",INDEX($T$5:$T$25,MATCH(LARGE($X$5:$X$25,3),$X$5:$X$25,0))),"") | C12: =IFERROR(IF(LARGE($X$5:$X$25,3)<=0,"",INDEX($R$5:$R$25,MATCH(LARGE($X$5:$X$25,3),$X$5:$X$25,0))),"") | D12: =IFERROR(IF(LARGE($X$5:$X$25,3)<=0,"",INDEX($S$5:$S$25,MATCH(LARGE($X$5:$X$25,3),$X$5:$X$25,0))),"") | E12: =IFERROR(IF(LARGE($X$5:$X$25,3)<=0,"",INDEX($W$5:$W$25,MATCH(LARGE($X$5:$X$25,3),$X$5:$X$25,0))),"") | F12: =IFERROR(IF(LARGE($X$5:$X$25,3)<=0,"",INDEX($V$5:$V$25,MATCH(LARGE($X$5:$X$25,3),$X$5:$X$25,0))),"") | M12: ='Simulateur'!D17 | N12: =IFERROR(INDEX('Bibliothèque constats'!$B$5:$B$88,MATCH($M12,'Bibliothèque constats'!$A$5:$A$88,0)),"") | O12: =IFERROR(INDEX('Bibliothèque constats'!$F$5:$F$88,MATCH($M12,'Bibliothèque constats'!$A$5:$A$88,0)),"") | P12: =IFERROR(INDEX('Bibliothèque constats'!$G$5:$G$88,MATCH($M12,'Bibliothèque constats'!$A$5:$A$88,0)),"") | Q12: =IFERROR(INDEX('Bibliothèque constats'!$H$5:$H$88,MATCH($M12,'Bibliothèque constats'!$A$5:$A$88,0)),"") | R12: =IFERROR(INDEX('Bibliothèque constats'!$I$5:$I$88,MATCH($M12,'Bibliothèque constats'!$A$5:$A$88,0)),"") | S12: =IFERROR(INDEX('Bibliothèque constats'!$J$5:$J$88,MATCH($M12,'Bibliothèque constats'!$A$5:$A$88,0)),"") | T12: =IFERROR(INDEX('Bibliothèque constats'!$K$5:$K$88,MATCH($M12,'Bibliothèque constats'!$A$5:$A$88,0)),"") | U12: =IFERROR(INDEX('Bibliothèque constats'!$L$5:$L$88,MATCH($M12,'Bibliothèque constats'!$A$5:$A$88,0)),"") | V12: =IFERROR(INDEX('Bibliothèque constats'!$M$5:$M$88,MATCH($M12,'Bibliothèque constats'!$A$5:$A$88,0)),"") | W12: =IFERROR(INDEX('Bibliothèque constats'!$E$5:$E$88,MATCH($M12,'Bibliothèque constats'!$A$5:$A$88,0)),"") | X12: =IF(AND(Q12>0,T12<>""),Q12*1000-ROW(),0) | Y12: =IF(P12="Force",1000-ROW(),0)
A13: =IF(LARGE($X$5:$X$25,4)<=0,"",4) | B13: =IFERROR(IF(LARGE($X$5:$X$25,4)<=0,"",INDEX($T$5:$T$25,MATCH(LARGE($X$5:$X$25,4),$X$5:$X$25,0))),"") | C13: =IFERROR(IF(LARGE($X$5:$X$25,4)<=0,"",INDEX($R$5:$R$25,MATCH(LARGE($X$5:$X$25,4),$X$5:$X$25,0))),"") | D13: =IFERROR(IF(LARGE($X$5:$X$25,4)<=0,"",INDEX($S$5:$S$25,MATCH(LARGE($X$5:$X$25,4),$X$5:$X$25,0))),"") | E13: =IFERROR(IF(LARGE($X$5:$X$25,4)<=0,"",INDEX($W$5:$W$25,MATCH(LARGE($X$5:$X$25,4),$X$5:$X$25,0))),"") | F13: =IFERROR(IF(LARGE($X$5:$X$25,4)<=0,"",INDEX($V$5:$V$25,MATCH(LARGE($X$5:$X$25,4),$X$5:$X$25,0))),"") | M13: ='Simulateur'!D18 | N13: =IFERROR(INDEX('Bibliothèque constats'!$B$5:$B$88,MATCH($M13,'Bibliothèque constats'!$A$5:$A$88,0)),"") | O13: =IFERROR(INDEX('Bibliothèque constats'!$F$5:$F$88,MATCH($M13,'Bibliothèque constats'!$A$5:$A$88,0)),"") | P13: =IFERROR(INDEX('Bibliothèque constats'!$G$5:$G$88,MATCH($M13,'Bibliothèque constats'!$A$5:$A$88,0)),"") | Q13: =IFERROR(INDEX('Bibliothèque constats'!$H$5:$H$88,MATCH($M13,'Bibliothèque constats'!$A$5:$A$88,0)),"") | R13: =IFERROR(INDEX('Bibliothèque constats'!$I$5:$I$88,MATCH($M13,'Bibliothèque constats'!$A$5:$A$88,0)),"") | S13: =IFERROR(INDEX('Bibliothèque constats'!$J$5:$J$88,MATCH($M13,'Bibliothèque constats'!$A$5:$A$88,0)),"") | T13: =IFERROR(INDEX('Bibliothèque constats'!$K$5:$K$88,MATCH($M13,'Bibliothèque constats'!$A$5:$A$88,0)),"") | U13: =IFERROR(INDEX('Bibliothèque constats'!$L$5:$L$88,MATCH($M13,'Bibliothèque constats'!$A$5:$A$88,0)),"") | V13: =IFERROR(INDEX('Bibliothèque constats'!$M$5:$M$88,MATCH($M13,'Bibliothèque constats'!$A$5:$A$88,0)),"") | W13: =IFERROR(INDEX('Bibliothèque constats'!$E$5:$E$88,MATCH($M13,'Bibliothèque constats'!$A$5:$A$88,0)),"") | X13: =IF(AND(Q13>0,T13<>""),Q13*1000-ROW(),0) | Y13: =IF(P13="Force",1000-ROW(),0)
A14: =IF(LARGE($X$5:$X$25,5)<=0,"",5) | B14: =IFERROR(IF(LARGE($X$5:$X$25,5)<=0,"",INDEX($T$5:$T$25,MATCH(LARGE($X$5:$X$25,5),$X$5:$X$25,0))),"") | C14: =IFERROR(IF(LARGE($X$5:$X$25,5)<=0,"",INDEX($R$5:$R$25,MATCH(LARGE($X$5:$X$25,5),$X$5:$X$25,0))),"") | D14: =IFERROR(IF(LARGE($X$5:$X$25,5)<=0,"",INDEX($S$5:$S$25,MATCH(LARGE($X$5:$X$25,5),$X$5:$X$25,0))),"") | E14: =IFERROR(IF(LARGE($X$5:$X$25,5)<=0,"",INDEX($W$5:$W$25,MATCH(LARGE($X$5:$X$25,5),$X$5:$X$25,0))),"") | F14: =IFERROR(IF(LARGE($X$5:$X$25,5)<=0,"",INDEX($V$5:$V$25,MATCH(LARGE($X$5:$X$25,5),$X$5:$X$25,0))),"") | M14: ='Simulateur'!D19 | N14: =IFERROR(INDEX('Bibliothèque constats'!$B$5:$B$88,MATCH($M14,'Bibliothèque constats'!$A$5:$A$88,0)),"") | O14: =IFERROR(INDEX('Bibliothèque constats'!$F$5:$F$88,MATCH($M14,'Bibliothèque constats'!$A$5:$A$88,0)),"") | P14: =IFERROR(INDEX('Bibliothèque constats'!$G$5:$G$88,MATCH($M14,'Bibliothèque constats'!$A$5:$A$88,0)),"") | Q14: =IFERROR(INDEX('Bibliothèque constats'!$H$5:$H$88,MATCH($M14,'Bibliothèque constats'!$A$5:$A$88,0)),"") | R14: =IFERROR(INDEX('Bibliothèque constats'!$I$5:$I$88,MATCH($M14,'Bibliothèque constats'!$A$5:$A$88,0)),"") | S14: =IFERROR(INDEX('Bibliothèque constats'!$J$5:$J$88,MATCH($M14,'Bibliothèque constats'!$A$5:$A$88,0)),"") | T14: =IFERROR(INDEX('Bibliothèque constats'!$K$5:$K$88,MATCH($M14,'Bibliothèque constats'!$A$5:$A$88,0)),"") | U14: =IFERROR(INDEX('Bibliothèque constats'!$L$5:$L$88,MATCH($M14,'Bibliothèque constats'!$A$5:$A$88,0)),"") | V14: =IFERROR(INDEX('Bibliothèque constats'!$M$5:$M$88,MATCH($M14,'Bibliothèque constats'!$A$5:$A$88,0)),"") | W14: =IFERROR(INDEX('Bibliothèque constats'!$E$5:$E$88,MATCH($M14,'Bibliothèque constats'!$A$5:$A$88,0)),"") | X14: =IF(AND(Q14>0,T14<>""),Q14*1000-ROW(),0) | Y14: =IF(P14="Force",1000-ROW(),0)
A15: =IF(LARGE($X$5:$X$25,6)<=0,"",6) | B15: =IFERROR(IF(LARGE($X$5:$X$25,6)<=0,"",INDEX($T$5:$T$25,MATCH(LARGE($X$5:$X$25,6),$X$5:$X$25,0))),"") | C15: =IFERROR(IF(LARGE($X$5:$X$25,6)<=0,"",INDEX($R$5:$R$25,MATCH(LARGE($X$5:$X$25,6),$X$5:$X$25,0))),"") | D15: =IFERROR(IF(LARGE($X$5:$X$25,6)<=0,"",INDEX($S$5:$S$25,MATCH(LARGE($X$5:$X$25,6),$X$5:$X$25,0))),"") | E15: =IFERROR(IF(LARGE($X$5:$X$25,6)<=0,"",INDEX($W$5:$W$25,MATCH(LARGE($X$5:$X$25,6),$X$5:$X$25,0))),"") | F15: =IFERROR(IF(LARGE($X$5:$X$25,6)<=0,"",INDEX($V$5:$V$25,MATCH(LARGE($X$5:$X$25,6),$X$5:$X$25,0))),"") | M15: ='Simulateur'!D20 | N15: =IFERROR(INDEX('Bibliothèque constats'!$B$5:$B$88,MATCH($M15,'Bibliothèque constats'!$A$5:$A$88,0)),"") | O15: =IFERROR(INDEX('Bibliothèque constats'!$F$5:$F$88,MATCH($M15,'Bibliothèque constats'!$A$5:$A$88,0)),"") | P15: =IFERROR(INDEX('Bibliothèque constats'!$G$5:$G$88,MATCH($M15,'Bibliothèque constats'!$A$5:$A$88,0)),"") | Q15: =IFERROR(INDEX('Bibliothèque constats'!$H$5:$H$88,MATCH($M15,'Bibliothèque constats'!$A$5:$A$88,0)),"") | R15: =IFERROR(INDEX('Bibliothèque constats'!$I$5:$I$88,MATCH($M15,'Bibliothèque constats'!$A$5:$A$88,0)),"") | S15: =IFERROR(INDEX('Bibliothèque constats'!$J$5:$J$88,MATCH($M15,'Bibliothèque constats'!$A$5:$A$88,0)),"") | T15: =IFERROR(INDEX('Bibliothèque constats'!$K$5:$K$88,MATCH($M15,'Bibliothèque constats'!$A$5:$A$88,0)),"") | U15: =IFERROR(INDEX('Bibliothèque constats'!$L$5:$L$88,MATCH($M15,'Bibliothèque constats'!$A$5:$A$88,0)),"") | V15: =IFERROR(INDEX('Bibliothèque constats'!$M$5:$M$88,MATCH($M15,'Bibliothèque constats'!$A$5:$A$88,0)),"") | W15: =IFERROR(INDEX('Bibliothèque constats'!$E$5:$E$88,MATCH($M15,'Bibliothèque constats'!$A$5:$A$88,0)),"") | X15: =IF(AND(Q15>0,T15<>""),Q15*1000-ROW(),0) | Y15: =IF(P15="Force",1000-ROW(),0)
M16: ='Simulateur'!D21 | N16: =IFERROR(INDEX('Bibliothèque constats'!$B$5:$B$88,MATCH($M16,'Bibliothèque constats'!$A$5:$A$88,0)),"") | O16: =IFERROR(INDEX('Bibliothèque constats'!$F$5:$F$88,MATCH($M16,'Bibliothèque constats'!$A$5:$A$88,0)),"") | P16: =IFERROR(INDEX('Bibliothèque constats'!$G$5:$G$88,MATCH($M16,'Bibliothèque constats'!$A$5:$A$88,0)),"") | Q16: =IFERROR(INDEX('Bibliothèque constats'!$H$5:$H$88,MATCH($M16,'Bibliothèque constats'!$A$5:$A$88,0)),"") | R16: =IFERROR(INDEX('Bibliothèque constats'!$I$5:$I$88,MATCH($M16,'Bibliothèque constats'!$A$5:$A$88,0)),"") | S16: =IFERROR(INDEX('Bibliothèque constats'!$J$5:$J$88,MATCH($M16,'Bibliothèque constats'!$A$5:$A$88,0)),"") | T16: =IFERROR(INDEX('Bibliothèque constats'!$K$5:$K$88,MATCH($M16,'Bibliothèque constats'!$A$5:$A$88,0)),"") | U16: =IFERROR(INDEX('Bibliothèque constats'!$L$5:$L$88,MATCH($M16,'Bibliothèque constats'!$A$5:$A$88,0)),"") | V16: =IFERROR(INDEX('Bibliothèque constats'!$M$5:$M$88,MATCH($M16,'Bibliothèque constats'!$A$5:$A$88,0)),"") | W16: =IFERROR(INDEX('Bibliothèque constats'!$E$5:$E$88,MATCH($M16,'Bibliothèque constats'!$A$5:$A$88,0)),"") | X16: =IF(AND(Q16>0,T16<>""),Q16*1000-ROW(),0) | Y16: =IF(P16="Force",1000-ROW(),0)
A17: Forces et pratiques déjà en place | M17: ='Simulateur'!D22 | N17: =IFERROR(INDEX('Bibliothèque constats'!$B$5:$B$88,MATCH($M17,'Bibliothèque constats'!$A$5:$A$88,0)),"") | O17: =IFERROR(INDEX('Bibliothèque constats'!$F$5:$F$88,MATCH($M17,'Bibliothèque constats'!$A$5:$A$88,0)),"") | P17: =IFERROR(INDEX('Bibliothèque constats'!$G$5:$G$88,MATCH($M17,'Bibliothèque constats'!$A$5:$A$88,0)),"") | Q17: =IFERROR(INDEX('Bibliothèque constats'!$H$5:$H$88,MATCH($M17,'Bibliothèque constats'!$A$5:$A$88,0)),"") | R17: =IFERROR(INDEX('Bibliothèque constats'!$I$5:$I$88,MATCH($M17,'Bibliothèque constats'!$A$5:$A$88,0)),"") | S17: =IFERROR(INDEX('Bibliothèque constats'!$J$5:$J$88,MATCH($M17,'Bibliothèque constats'!$A$5:$A$88,0)),"") | T17: =IFERROR(INDEX('Bibliothèque constats'!$K$5:$K$88,MATCH($M17,'Bibliothèque constats'!$A$5:$A$88,0)),"") | U17: =IFERROR(INDEX('Bibliothèque constats'!$L$5:$L$88,MATCH($M17,'Bibliothèque constats'!$A$5:$A$88,0)),"") | V17: =IFERROR(INDEX('Bibliothèque constats'!$M$5:$M$88,MATCH($M17,'Bibliothèque constats'!$A$5:$A$88,0)),"") | W17: =IFERROR(INDEX('Bibliothèque constats'!$E$5:$E$88,MATCH($M17,'Bibliothèque constats'!$A$5:$A$88,0)),"") | X17: =IF(AND(Q17>0,T17<>""),Q17*1000-ROW(),0) | Y17: =IF(P17="Force",1000-ROW(),0)
A18: # | B18: Force / pratique observée | C18: Dimension | D18: Réponse sélectionnée | E18: Question pour capitaliser | M18: ='Simulateur'!D23 | N18: =IFERROR(INDEX('Bibliothèque constats'!$B$5:$B$88,MATCH($M18,'Bibliothèque constats'!$A$5:$A$88,0)),"") | O18: =IFERROR(INDEX('Bibliothèque constats'!$F$5:$F$88,MATCH($M18,'Bibliothèque constats'!$A$5:$A$88,0)),"") | P18: =IFERROR(INDEX('Bibliothèque constats'!$G$5:$G$88,MATCH($M18,'Bibliothèque constats'!$A$5:$A$88,0)),"") | Q18: =IFERROR(INDEX('Bibliothèque constats'!$H$5:$H$88,MATCH($M18,'Bibliothèque constats'!$A$5:$A$88,0)),"") | R18: =IFERROR(INDEX('Bibliothèque constats'!$I$5:$I$88,MATCH($M18,'Bibliothèque constats'!$A$5:$A$88,0)),"") | S18: =IFERROR(INDEX('Bibliothèque constats'!$J$5:$J$88,MATCH($M18,'Bibliothèque constats'!$A$5:$A$88,0)),"") | T18: =IFERROR(INDEX('Bibliothèque constats'!$K$5:$K$88,MATCH($M18,'Bibliothèque constats'!$A$5:$A$88,0)),"") | U18: =IFERROR(INDEX('Bibliothèque constats'!$L$5:$L$88,MATCH($M18,'Bibliothèque constats'!$A$5:$A$88,0)),"") | V18: =IFERROR(INDEX('Bibliothèque constats'!$M$5:$M$88,MATCH($M18,'Bibliothèque constats'!$A$5:$A$88,0)),"") | W18: =IFERROR(INDEX('Bibliothèque constats'!$E$5:$E$88,MATCH($M18,'Bibliothèque constats'!$A$5:$A$88,0)),"") | X18: =IF(AND(Q18>0,T18<>""),Q18*1000-ROW(),0) | Y18: =IF(P18="Force",1000-ROW(),0)
A19: =IF(LARGE($Y$5:$Y$25,1)<=0,"",1) | B19: =IFERROR(IF(LARGE($Y$5:$Y$25,1)<=0,"",INDEX($S$5:$S$25,MATCH(LARGE($Y$5:$Y$25,1),$Y$5:$Y$25,0))),"") | C19: =IFERROR(IF(LARGE($Y$5:$Y$25,1)<=0,"",INDEX($O$5:$O$25,MATCH(LARGE($Y$5:$Y$25,1),$Y$5:$Y$25,0))),"") | D19: =IFERROR(IF(LARGE($Y$5:$Y$25,1)<=0,"",INDEX($W$5:$W$25,MATCH(LARGE($Y$5:$Y$25,1),$Y$5:$Y$25,0))),"") | E19: =IFERROR(IF(LARGE($Y$5:$Y$25,1)<=0,"",INDEX($V$5:$V$25,MATCH(LARGE($Y$5:$Y$25,1),$Y$5:$Y$25,0))),"") | M19: ='Simulateur'!D40 | N19: =IFERROR(INDEX('Bibliothèque constats'!$B$5:$B$88,MATCH($M19,'Bibliothèque constats'!$A$5:$A$88,0)),"") | O19: =IFERROR(INDEX('Bibliothèque constats'!$F$5:$F$88,MATCH($M19,'Bibliothèque constats'!$A$5:$A$88,0)),"") | P19: =IFERROR(INDEX('Bibliothèque constats'!$G$5:$G$88,MATCH($M19,'Bibliothèque constats'!$A$5:$A$88,0)),"") | Q19: =IFERROR(INDEX('Bibliothèque constats'!$H$5:$H$88,MATCH($M19,'Bibliothèque constats'!$A$5:$A$88,0)),"") | R19: =IFERROR(INDEX('Bibliothèque constats'!$I$5:$I$88,MATCH($M19,'Bibliothèque constats'!$A$5:$A$88,0)),"") | S19: =IFERROR(INDEX('Bibliothèque constats'!$J$5:$J$88,MATCH($M19,'Bibliothèque constats'!$A$5:$A$88,0)),"") | T19: =IFERROR(INDEX('Bibliothèque constats'!$K$5:$K$88,MATCH($M19,'Bibliothèque constats'!$A$5:$A$88,0)),"") | U19: =IFERROR(INDEX('Bibliothèque constats'!$L$5:$L$88,MATCH($M19,'Bibliothèque constats'!$A$5:$A$88,0)),"") | V19: =IFERROR(INDEX('Bibliothèque constats'!$M$5:$M$88,MATCH($M19,'Bibliothèque constats'!$A$5:$A$88,0)),"") | W19: =IFERROR(INDEX('Bibliothèque constats'!$E$5:$E$88,MATCH($M19,'Bibliothèque constats'!$A$5:$A$88,0)),"") | X19: =IF(AND(Q19>0,T19<>""),Q19*1000-ROW(),0) | Y19: =IF(P19="Force",1000-ROW(),0)
A20: =IF(LARGE($Y$5:$Y$25,2)<=0,"",2) | B20: =IFERROR(IF(LARGE($Y$5:$Y$25,2)<=0,"",INDEX($S$5:$S$25,MATCH(LARGE($Y$5:$Y$25,2),$Y$5:$Y$25,0))),"") | C20: =IFERROR(IF(LARGE($Y$5:$Y$25,2)<=0,"",INDEX($O$5:$O$25,MATCH(LARGE($Y$5:$Y$25,2),$Y$5:$Y$25,0))),"") | D20: =IFERROR(IF(LARGE($Y$5:$Y$25,2)<=0,"",INDEX($W$5:$W$25,MATCH(LARGE($Y$5:$Y$25,2),$Y$5:$Y$25,0))),"") | E20: =IFERROR(IF(LARGE($Y$5:$Y$25,2)<=0,"",INDEX($V$5:$V$25,MATCH(LARGE($Y$5:$Y$25,2),$Y$5:$Y$25,0))),"") | M20: ='Simulateur'!D41 | N20: =IFERROR(INDEX('Bibliothèque constats'!$B$5:$B$88,MATCH($M20,'Bibliothèque constats'!$A$5:$A$88,0)),"") | O20: =IFERROR(INDEX('Bibliothèque constats'!$F$5:$F$88,MATCH($M20,'Bibliothèque constats'!$A$5:$A$88,0)),"") | P20: =IFERROR(INDEX('Bibliothèque constats'!$G$5:$G$88,MATCH($M20,'Bibliothèque constats'!$A$5:$A$88,0)),"") | Q20: =IFERROR(INDEX('Bibliothèque constats'!$H$5:$H$88,MATCH($M20,'Bibliothèque constats'!$A$5:$A$88,0)),"") | R20: =IFERROR(INDEX('Bibliothèque constats'!$I$5:$I$88,MATCH($M20,'Bibliothèque constats'!$A$5:$A$88,0)),"") | S20: =IFERROR(INDEX('Bibliothèque constats'!$J$5:$J$88,MATCH($M20,'Bibliothèque constats'!$A$5:$A$88,0)),"") | T20: =IFERROR(INDEX('Bibliothèque constats'!$K$5:$K$88,MATCH($M20,'Bibliothèque constats'!$A$5:$A$88,0)),"") | U20: =IFERROR(INDEX('Bibliothèque constats'!$L$5:$L$88,MATCH($M20,'Bibliothèque constats'!$A$5:$A$88,0)),"") | V20: =IFERROR(INDEX('Bibliothèque constats'!$M$5:$M$88,MATCH($M20,'Bibliothèque constats'!$A$5:$A$88,0)),"") | W20: =IFERROR(INDEX('Bibliothèque constats'!$E$5:$E$88,MATCH($M20,'Bibliothèque constats'!$A$5:$A$88,0)),"") | X20: =IF(AND(Q20>0,T20<>""),Q20*1000-ROW(),0) | Y20: =IF(P20="Force",1000-ROW(),0)
A21: =IF(LARGE($Y$5:$Y$25,3)<=0,"",3) | B21: =IFERROR(IF(LARGE($Y$5:$Y$25,3)<=0,"",INDEX($S$5:$S$25,MATCH(LARGE($Y$5:$Y$25,3),$Y$5:$Y$25,0))),"") | C21: =IFERROR(IF(LARGE($Y$5:$Y$25,3)<=0,"",INDEX($O$5:$O$25,MATCH(LARGE($Y$5:$Y$25,3),$Y$5:$Y$25,0))),"") | D21: =IFERROR(IF(LARGE($Y$5:$Y$25,3)<=0,"",INDEX($W$5:$W$25,MATCH(LARGE($Y$5:$Y$25,3),$Y$5:$Y$25,0))),"") | E21: =IFERROR(IF(LARGE($Y$5:$Y$25,3)<=0,"",INDEX($V$5:$V$25,MATCH(LARGE($Y$5:$Y$25,3),$Y$5:$Y$25,0))),"") | M21: ='Simulateur'!D42 | N21: =IFERROR(INDEX('Bibliothèque constats'!$B$5:$B$88,MATCH($M21,'Bibliothèque constats'!$A$5:$A$88,0)),"") | O21: =IFERROR(INDEX('Bibliothèque constats'!$F$5:$F$88,MATCH($M21,'Bibliothèque constats'!$A$5:$A$88,0)),"") | P21: =IFERROR(INDEX('Bibliothèque constats'!$G$5:$G$88,MATCH($M21,'Bibliothèque constats'!$A$5:$A$88,0)),"") | Q21: =IFERROR(INDEX('Bibliothèque constats'!$H$5:$H$88,MATCH($M21,'Bibliothèque constats'!$A$5:$A$88,0)),"") | R21: =IFERROR(INDEX('Bibliothèque constats'!$I$5:$I$88,MATCH($M21,'Bibliothèque constats'!$A$5:$A$88,0)),"") | S21: =IFERROR(INDEX('Bibliothèque constats'!$J$5:$J$88,MATCH($M21,'Bibliothèque constats'!$A$5:$A$88,0)),"") | T21: =IFERROR(INDEX('Bibliothèque constats'!$K$5:$K$88,MATCH($M21,'Bibliothèque constats'!$A$5:$A$88,0)),"") | U21: =IFERROR(INDEX('Bibliothèque constats'!$L$5:$L$88,MATCH($M21,'Bibliothèque constats'!$A$5:$A$88,0)),"") | V21: =IFERROR(INDEX('Bibliothèque constats'!$M$5:$M$88,MATCH($M21,'Bibliothèque constats'!$A$5:$A$88,0)),"") | W21: =IFERROR(INDEX('Bibliothèque constats'!$E$5:$E$88,MATCH($M21,'Bibliothèque constats'!$A$5:$A$88,0)),"") | X21: =IF(AND(Q21>0,T21<>""),Q21*1000-ROW(),0) | Y21: =IF(P21="Force",1000-ROW(),0)
A22: =IF(LARGE($Y$5:$Y$25,4)<=0,"",4) | B22: =IFERROR(IF(LARGE($Y$5:$Y$25,4)<=0,"",INDEX($S$5:$S$25,MATCH(LARGE($Y$5:$Y$25,4),$Y$5:$Y$25,0))),"") | C22: =IFERROR(IF(LARGE($Y$5:$Y$25,4)<=0,"",INDEX($O$5:$O$25,MATCH(LARGE($Y$5:$Y$25,4),$Y$5:$Y$25,0))),"") | D22: =IFERROR(IF(LARGE($Y$5:$Y$25,4)<=0,"",INDEX($W$5:$W$25,MATCH(LARGE($Y$5:$Y$25,4),$Y$5:$Y$25,0))),"") | E22: =IFERROR(IF(LARGE($Y$5:$Y$25,4)<=0,"",INDEX($V$5:$V$25,MATCH(LARGE($Y$5:$Y$25,4),$Y$5:$Y$25,0))),"") | M22: ='Simulateur'!D43 | N22: =IFERROR(INDEX('Bibliothèque constats'!$B$5:$B$88,MATCH($M22,'Bibliothèque constats'!$A$5:$A$88,0)),"") | O22: =IFERROR(INDEX('Bibliothèque constats'!$F$5:$F$88,MATCH($M22,'Bibliothèque constats'!$A$5:$A$88,0)),"") | P22: =IFERROR(INDEX('Bibliothèque constats'!$G$5:$G$88,MATCH($M22,'Bibliothèque constats'!$A$5:$A$88,0)),"") | Q22: =IFERROR(INDEX('Bibliothèque constats'!$H$5:$H$88,MATCH($M22,'Bibliothèque constats'!$A$5:$A$88,0)),"") | R22: =IFERROR(INDEX('Bibliothèque constats'!$I$5:$I$88,MATCH($M22,'Bibliothèque constats'!$A$5:$A$88,0)),"") | S22: =IFERROR(INDEX('Bibliothèque constats'!$J$5:$J$88,MATCH($M22,'Bibliothèque constats'!$A$5:$A$88,0)),"") | T22: =IFERROR(INDEX('Bibliothèque constats'!$K$5:$K$88,MATCH($M22,'Bibliothèque constats'!$A$5:$A$88,0)),"") | U22: =IFERROR(INDEX('Bibliothèque constats'!$L$5:$L$88,MATCH($M22,'Bibliothèque constats'!$A$5:$A$88,0)),"") | V22: =IFERROR(INDEX('Bibliothèque constats'!$M$5:$M$88,MATCH($M22,'Bibliothèque constats'!$A$5:$A$88,0)),"") | W22: =IFERROR(INDEX('Bibliothèque constats'!$E$5:$E$88,MATCH($M22,'Bibliothèque constats'!$A$5:$A$88,0)),"") | X22: =IF(AND(Q22>0,T22<>""),Q22*1000-ROW(),0) | Y22: =IF(P22="Force",1000-ROW(),0)
M23: ='Simulateur'!D44 | N23: =IFERROR(INDEX('Bibliothèque constats'!$B$5:$B$88,MATCH($M23,'Bibliothèque constats'!$A$5:$A$88,0)),"") | O23: =IFERROR(INDEX('Bibliothèque constats'!$F$5:$F$88,MATCH($M23,'Bibliothèque constats'!$A$5:$A$88,0)),"") | P23: =IFERROR(INDEX('Bibliothèque constats'!$G$5:$G$88,MATCH($M23,'Bibliothèque constats'!$A$5:$A$88,0)),"") | Q23: =IFERROR(INDEX('Bibliothèque constats'!$H$5:$H$88,MATCH($M23,'Bibliothèque constats'!$A$5:$A$88,0)),"") | R23: =IFERROR(INDEX('Bibliothèque constats'!$I$5:$I$88,MATCH($M23,'Bibliothèque constats'!$A$5:$A$88,0)),"") | S23: =IFERROR(INDEX('Bibliothèque constats'!$J$5:$J$88,MATCH($M23,'Bibliothèque constats'!$A$5:$A$88,0)),"") | T23: =IFERROR(INDEX('Bibliothèque constats'!$K$5:$K$88,MATCH($M23,'Bibliothèque constats'!$A$5:$A$88,0)),"") | U23: =IFERROR(INDEX('Bibliothèque constats'!$L$5:$L$88,MATCH($M23,'Bibliothèque constats'!$A$5:$A$88,0)),"") | V23: =IFERROR(INDEX('Bibliothèque constats'!$M$5:$M$88,MATCH($M23,'Bibliothèque constats'!$A$5:$A$88,0)),"") | W23: =IFERROR(INDEX('Bibliothèque constats'!$E$5:$E$88,MATCH($M23,'Bibliothèque constats'!$A$5:$A$88,0)),"") | X23: =IF(AND(Q23>0,T23<>""),Q23*1000-ROW(),0) | Y23: =IF(P23="Force",1000-ROW(),0)
A24: Informations utiles pour préparer l’échange | M24: ='Simulateur'!D45 | N24: =IFERROR(INDEX('Bibliothèque constats'!$B$5:$B$88,MATCH($M24,'Bibliothèque constats'!$A$5:$A$88,0)),"") | O24: =IFERROR(INDEX('Bibliothèque constats'!$F$5:$F$88,MATCH($M24,'Bibliothèque constats'!$A$5:$A$88,0)),"") | P24: =IFERROR(INDEX('Bibliothèque constats'!$G$5:$G$88,MATCH($M24,'Bibliothèque constats'!$A$5:$A$88,0)),"") | Q24: =IFERROR(INDEX('Bibliothèque constats'!$H$5:$H$88,MATCH($M24,'Bibliothèque constats'!$A$5:$A$88,0)),"") | R24: =IFERROR(INDEX('Bibliothèque constats'!$I$5:$I$88,MATCH($M24,'Bibliothèque constats'!$A$5:$A$88,0)),"") | S24: =IFERROR(INDEX('Bibliothèque constats'!$J$5:$J$88,MATCH($M24,'Bibliothèque constats'!$A$5:$A$88,0)),"") | T24: =IFERROR(INDEX('Bibliothèque constats'!$K$5:$K$88,MATCH($M24,'Bibliothèque constats'!$A$5:$A$88,0)),"") | U24: =IFERROR(INDEX('Bibliothèque constats'!$L$5:$L$88,MATCH($M24,'Bibliothèque constats'!$A$5:$A$88,0)),"") | V24: =IFERROR(INDEX('Bibliothèque constats'!$M$5:$M$88,MATCH($M24,'Bibliothèque constats'!$A$5:$A$88,0)),"") | W24: =IFERROR(INDEX('Bibliothèque constats'!$E$5:$E$88,MATCH($M24,'Bibliothèque constats'!$A$5:$A$88,0)),"") | X24: =IF(AND(Q24>0,T24<>""),Q24*1000-ROW(),0) | Y24: =IF(P24="Force",1000-ROW(),0)
A25: Canal de vente déclaré | C25: =IF(S15="","",S15&" Réponse : "&W15) | M25: ='Simulateur'!D46 | N25: =IFERROR(INDEX('Bibliothèque constats'!$B$5:$B$88,MATCH($M25,'Bibliothèque constats'!$A$5:$A$88,0)),"") | O25: =IFERROR(INDEX('Bibliothèque constats'!$F$5:$F$88,MATCH($M25,'Bibliothèque constats'!$A$5:$A$88,0)),"") | P25: =IFERROR(INDEX('Bibliothèque constats'!$G$5:$G$88,MATCH($M25,'Bibliothèque constats'!$A$5:$A$88,0)),"") | Q25: =IFERROR(INDEX('Bibliothèque constats'!$H$5:$H$88,MATCH($M25,'Bibliothèque constats'!$A$5:$A$88,0)),"") | R25: =IFERROR(INDEX('Bibliothèque constats'!$I$5:$I$88,MATCH($M25,'Bibliothèque constats'!$A$5:$A$88,0)),"") | S25: =IFERROR(INDEX('Bibliothèque constats'!$J$5:$J$88,MATCH($M25,'Bibliothèque constats'!$A$5:$A$88,0)),"") | T25: =IFERROR(INDEX('Bibliothèque constats'!$K$5:$K$88,MATCH($M25,'Bibliothèque constats'!$A$5:$A$88,0)),"") | U25: =IFERROR(INDEX('Bibliothèque constats'!$L$5:$L$88,MATCH($M25,'Bibliothèque constats'!$A$5:$A$88,0)),"") | V25: =IFERROR(INDEX('Bibliothèque constats'!$M$5:$M$88,MATCH($M25,'Bibliothèque constats'!$A$5:$A$88,0)),"") | W25: =IFERROR(INDEX('Bibliothèque constats'!$E$5:$E$88,MATCH($M25,'Bibliothèque constats'!$A$5:$A$88,0)),"") | X25: =IF(AND(Q25>0,T25<>""),Q25*1000-ROW(),0) | Y25: =IF(P25="Force",1000-ROW(),0)
A26: Condition d’adoption déclarée | C26: =IF(S17="","",S17&" Réponse : "&W17)
A27: Progrès prioritaire déclaré | C27: =IF(S18="","",S18&" Réponse : "&W18)
A28: Nature de différenciation déclarée | C28: =IF(S21="","",S21&" Réponse : "&W21)
